Workbook

Sheet MainParams
A1: SIMULATION SETTINGS | C1: INPUTS | D1: UNITS / EXPECTED INPUTS | H1: Notes
A2: Description of this File | C2: 510K years – with initial thickness | D2: This field is not read; it is for description of this run | H2: "Simulation starting year" is not used in the code, it is used to construct col F in this file
A3: Max Height (*5) | C3: N/A | D3: [m] | H3: Do not use Column G; and remember that the code is not using the "Unused Fields"
A4: Left X Limit (*5) | C4: N/A | D4: [m] | H4: If there is "ancient ice" the thickness for it has to be in column 0, in the thickness file
A5: Right X Limit (*5) | C5: N/A | D5: [m]
A6: Down Y Limit (*5) | C6: N/A | D6: [m]
A7: Up Y Limit (*5) | C7: N/A | D7: [m]
A8: Planet | C8: Mars | D8: Planet name: Earth, Mars. Pluto
A9: Materials Availalble in the Domain | C9: =_xlfn.TEXTJOIN(",",1,G:G) -> CO2,CO2,H2O,CO2,H2O,CO2,H2O,CO2,H2O,CO2,H2O,CO2 | D9: Col G is populated using Col C - and this cell is populated using Col G
A10: Min virtual layers in the model | C10: 5 | D10: [layers]
A11: Simulation starting year | C11: -510 | D11: [Thousands Yrs] ago: -600 means 600,000 yrs ago
A12: Min Resolution | C12: 3500 | D12: [m]
A13: Max Resolution | C13: 4000 | D13: [m]
A14: Domain Filename | C14: smalldomain.exp | D14: [include '.exp']
A15: Coordinates Filename | C15: coordinates.xlsx | D15: [include extension]
A17: 1 | B17: 2 | C17: 3 | D17: Unused Fields
A18: Final Time [yr] | B18: Surface Temp [K] | C18: IceType | D18: Informational Data (Input Files are used)
D19: H2O | E19: CO2 | F19: Time
A20: 0 | B20: 150 | C20: =IF(D20=0, "CO2", "H2O") -> H2O | D20: =IFERROR( HLOOKUP(A20,H2O_thicknesses!$1:$2,2, 0),0) -> 0.19660321 | E20: =IFERROR( HLOOKUP(A20,CO2_thicknesses!$1:$2,2),0) -> 0 | F20: =C11 -> -510 | G20: CO2
A21: =A20+1000 -> 1000 | B21: =B20 -> 150 | C21: =IF(D21=0, "CO2", "H2O") -> H2O | D21: =IFERROR( HLOOKUP(A21,H2O_thicknesses!$1:$2,2, 0),0) -> 0.19623957 | E21: =IFERROR( HLOOKUP(A21,CO2_thicknesses!$1:$2,2),0) -> 0 | F21: =F20+1 -> -509 | G21: =IF(C20<>C21,C21,"")
A22: =A21+1000 -> 2000 | B22: =B21 -> 150 | C22: =IF(D22=0, "CO2", "H2O") -> H2O | D22: =IFERROR( HLOOKUP(A22,H2O_thicknesses!$1:$2,2, 0),0) -> 0.19892165 | E22: =IFERROR( HLOOKUP(A22,CO2_thicknesses!$1:$2,2),0) -> 0 | F22: =F21+1 -> -508 | G22: =IF(C21<>C22,C22,"")
A23: =A22+1000 -> 3000 | B23: =B22 -> 150 | C23: =IF(D23=0, "CO2", "H2O") -> H2O | D23: =IFERROR( HLOOKUP(A23,H2O_thicknesses!$1:$2,2, 0),0) -> 0.19567031 | E23: =IFERROR( HLOOKUP(A23,CO2_thicknesses!$1:$2,2),0) -> 0 | F23: =F22+1 -> -507 | G23: =IF(C22<>C23,C23,"")
A24: =A23+1000 -> 4000 | B24: =B23 -> 150 | C24: =IF(D24=0, "CO2", "H2O") -> H2O | D24: =IFERROR( HLOOKUP(A24,H2O_thicknesses!$1:$2,2, 0),0) -> 0.19336561 | E24: =IFERROR( HLOOKUP(A24,CO2_thicknesses!$1:$2,2),0) -> 0 | F24: =F23+1 -> -506 | G24: =IF(C23<>C24,C24,"")
A25: =A24+1000 -> 5000 | B25: =B24 -> 150 | C25: =IF(D25=0, "CO2", "H2O") -> H2O | D25: =IFERROR( HLOOKUP(A25,H2O_thicknesses!$1:$2,2, 0),0) -> 0.19135865 | E25: =IFERROR( HLOOKUP(A25,CO2_thicknesses!$1:$2,2),0) -> 0 | F25: =F24+1 -> -505 | G25: =IF(C24<>C25,C25,"")
A26: =A25+1000 -> 6000 | B26: =B25 -> 150 | C26: =IF(D26=0, "CO2", "H2O") -> H2O | D26: =IFERROR( HLOOKUP(A26,H2O_thicknesses!$1:$2,2, 0),0) -> 0.19765021 | E26: =IFERROR( HLOOKUP(A26,CO2_thicknesses!$1:$2,2),0) -> 0 | F26: =F25+1 -> -504 | G26: =IF(C25<>C26,C26,"")
A27: =A26+1000 -> 7000 | B27: =B26 -> 150 | C27: =IF(D27=0, "CO2", "H2O") -> H2O | D27: =IFERROR( HLOOKUP(A27,H2O_thicknesses!$1:$2,2, 0),0) -> 0.19345645 | E27: =IFERROR( HLOOKUP(A27,CO2_thicknesses!$1:$2,2),0) -> 0 | F27: =F26+1 -> -503 | G27: =IF(C26<>C27,C27,"")
A28: =A27+1000 -> 8000 | B28: =B27 -> 150 | C28: =IF(D28=0, "CO2", "H2O") -> H2O | D28: =IFERROR( HLOOKUP(A28,H2O_thicknesses!$1:$2,2, 0),0) -> 0.19135208 | E28: =IFERROR( HLOOKUP(A28,CO2_thicknesses!$1:$2,2),0) -> 0 | F28: =F27+1 -> -502 | G28: =IF(C27<>C28,C28,"")
A29: =A28+1000 -> 9000 | B29: =B28 -> 150 | C29: =IF(D29=0, "CO2", "H2O") -> H2O | D29: =IFERROR( HLOOKUP(A29,H2O_thicknesses!$1:$2,2, 0),0) -> 0.19006791 | E29: =IFERROR( HLOOKUP(A29,CO2_thicknesses!$1:$2,2),0) -> 0 | F29: =F28+1 -> -501 | G29: =IF(C28<>C29,C29,"")
A30: =A29+1000 -> 10000 | B30: =B29 -> 150 | C30: =IF(D30=0, "CO2", "H2O") -> H2O | D30: =IFERROR( HLOOKUP(A30,H2O_thicknesses!$1:$2,2, 0),0) -> 0.19156339 | E30: =IFERROR( HLOOKUP(A30,CO2_thicknesses!$1:$2,2),0) -> 0 | F30: =F29+1 -> -500 | G30: =IF(C29<>C30,C30,"")
A31: =A30+1000 -> 11000 | B31: =B30 -> 150 | C31: =IF(D31=0, "CO2", "H2O") -> H2O | D31: =IFERROR( HLOOKUP(A31,H2O_thicknesses!$1:$2,2, 0),0) -> 0.1939824 | E31: =IFERROR( HLOOKUP(A31,CO2_thicknesses!$1:$2,2),0) -> 0 | F31: =F30+1 -> -499 | G31: =IF(C30<>C31,C31,"")
A32: =A31+1000 -> 12000 | B32: =B31 -> 150 | C32: =IF(D32=0, "CO2", "H2O") -> H2O | D32: =IFERROR( HLOOKUP(A32,H2O_thicknesses!$1:$2,2, 0),0) -> 0.19294044 | E32: =IFERROR( HLOOKUP(A32,CO2_thicknesses!$1:$2,2),0) -> 0 | F32: =F31+1 -> -498 | G32: =IF(C31<>C32,C32,"")
... A270: =A269+1000 -> 250000 | B270: =B269 -> 150 | C270: =IF(D270=0, "CO2", "H2O") -> CO2 | D270: =IFERROR( HLOOKUP(A270,H2O_thicknesses!$1:$2,2, 0),0) -> 0 | E270: =IFERROR( HLOOKUP(A270,CO2_thicknesses!$1:$2,2),0) -> 0 | F270: =F269+1 -> -260 | G270: =IF(C269<>C270,C270,"")
A271: =A270+1000 -> 251000 | B271: =B270 -> 150 | C271: =IF(D271=0, "CO2", "H2O") -> CO2 | D271: =IFERROR( HLOOKUP(A271,H2O_thicknesses!$1:$2,2, 0),0) -> 0 | E271: =IFERROR( HLOOKUP(A271,CO2_thicknesses!$1:$2,2),0) -> 0 | F271: =F270+1 -> -259 | G271: =IF(C270<>C271,C271,"") | H271: 0.00014967487
A272: =A271+1000 -> 252000 | B272: =B271 -> 150 | C272: =IF(D272=0, "CO2", "H2O") -> CO2 | D272: =IFERROR( HLOOKUP(A272,H2O_thicknesses!$1:$2,2, 0),0) -> 0 | E272: =IFERROR( HLOOKUP(A272,CO2_thicknesses!$1:$2,2),0) -> 0 | F272: =F271+1 -> -258 | G272: =IF(C271<>C272,C272,"")
A273: =A272+1000 -> 253000 | B273: =B272 -> 150 | C273: =IF(D273=0, "CO2", "H2O") -> CO2 | D273: =IFERROR( HLOOKUP(A273,H2O_thicknesses!$1:$2,2, 0),0) -> 0 | E273: =IFERROR( HLOOKUP(A273,CO2_thicknesses!$1:$2,2),0) -> 0 | F273: =F272+1 -> -257 | G273: =IF(C272<>C273,C273,"")
A274: =A273+1000 -> 254000 | B274: =B273 -> 150 | C274: =IF(D274=0, "CO2", "H2O") -> CO2 | D274: =IFERROR( HLOOKUP(A274,H2O_thicknesses!$1:$2,2, 0),0) -> 0 | E274: =IFERROR( HLOOKUP(A274,CO2_thicknesses!$1:$2,2),0) -> 0 | F274: =F273+1 -> -256 | G274: =IF(C273<>C274,C274,"")
A275: =A274+1000 -> 255000 | B275: =B274 -> 150 | C275: =IF(D275=0, "CO2", "H2O") -> CO2 | D275: =IFERROR( HLOOKUP(A275,H2O_thicknesses!$1:$2,2, 0),0) -> 0 | E275: =IFERROR( HLOOKUP(A275,CO2_thicknesses!$1:$2,2),0) -> 0.45360352 | F275: =F274+1 -> -255 | G275: =IF(C274<>C275,C275,"")
A276: =A275+1000 -> 256000 | B276: =B275 -> 150 | C276: =IF(D276=0, "CO2", "H2O") -> CO2 | D276: =IFERROR( HLOOKUP(A276,H2O_thicknesses!$1:$2,2, 0),0) -> 0 | E276: =IFERROR( HLOOKUP(A276,CO2_thicknesses!$1:$2,2),0) -> -1.5651036 | F276: =F275+1 -> -254 | G276: =IF(C275<>C276,C276,"")
A277: =A276+1000 -> 257000 | B277: =B276 -> 150 | C277: =IF(D277=0, "CO2", "H2O") -> CO2 | D277: =IFERROR( HLOOKUP(A277,H2O_thicknesses!$1:$2,2, 0),0) -> 0 | E277: =IFERROR( HLOOKUP(A277,CO2_thicknesses!$1:$2,2),0) -> -1.5651036 | F277: =F276+1 -> -253 | G277: =IF(C276<>C277,C277,"")
A278: =A277+1000 -> 258000 | B278: =B277 -> 150 | C278: =IF(D278=0, "CO2", "H2O") -> CO2 | D278: =IFERROR( HLOOKUP(A278,H2O_thicknesses!$1:$2,2, 0),0) -> 0 | E278: =IFERROR( HLOOKUP(A278,CO2_thicknesses!$1:$2,2),0) -> -1.5651036 | F278: =F277+1 -> -252 | G278: =IF(C277<>C278,C278,"")
...

Sheet CO2_thicknesses
A1: 510000 | B1: =A1-1000 -> 509000 | C1: =B1-1000 -> 508000 | D1: =C1-1000 -> 507000 | E1: =D1-1000 -> 506000 | F1: =E1-1000 -> 505000 | G1: =F1-1000 -> 504000 | H1: =G1-1000 -> 503000 | I1: =H1-1000 -> 502000 | ... SQ1: =SP1-1000 -> 0
A2: 1 | B2: 0.28033761 | C2: 0.44535876 | D2: 0.60707916 | E2: 0.85408283 | F2: 1.2288704 | G2: 1.3734732 | H2: 1.5345611 | I2: 1.8475998 | J2: 2.0699103 | K2: 2.218977 | L2: 2.4015444 | M2: 3.3049805 | N2: 3.4932298 | O2: 3.6682876 | P2: 3.6742952 | Q2: 3.7260926 | R2: 3.8870431 | S2: 4.0004161 | T2: 3.8925829 | U2: 4.3942002 | V2: 4.865072 | W2: 4.9538526 | X2: 4.99825 | Y2: 5.0892424 | Z2: 5.1429734 | AA2: 5.1774637 | AB2: 5.6512699 | AC2: 5.6754588 | AD2: 5.6550388 | AE2: 5.6498769 | AF2: 5.5720435 | AG2: 5.5698272 | AH2: 5.364458 | AI2: 5.2320611 | AJ2: 4.9364886 | AK2: 4.7354466 | AL2: 4.6644711 | AM2: 4.5995028 | AN2: 4.4831443 | AO2: 3.5261265 | AP2: 3.3407383 | AQ2: 3.1937496 | AR2: 3.0332556 | AS2: 2.8600584 | AT2: 2.8198034 | AU2: 2.586078 | AV2: 2.3287287 | AW2: 2.0743791 | AX2: 1.7701558 | AY2: 1.307281 | AZ2: 1.0862821 | BA2: 0.88846824 | BB2: 0.68397873 | BC2: 0.49048233 | BD2: 0.42125985 | BE2: 0.25482407 | BF2: 0.090274053 | BG2: -0.079196458 | BH2: -0.20796945 | BI2: -0.33014555 | BJ2: -0.45401753 | BK2: -0.56301168 | BL2: -0.69209294 | BM2: -0.79572814 | BN2: -1.2625148 | BO2: -1.5157884 | BP2: -1.6385499 | BQ2: -1.7542806 | BR2: -1.8584935 | BS2: -2.1940787 | BT2: -2.3141548 | BU2: -2.4039438 | BV2: -2.4674752 | BW2: -2.5672665 | BX2: -2.7126368 | BY2: -2.7397215 | BZ2: -2.7733957 | CA2: -3.0783005 | CB2: -3.1777138 | CC2: -3.1525705 | CD2: -3.1519395 | CE2: -3.1564274 | CF2: -3.0261108 | CG2: -2.9347387 | CH2: -2.9268268 | CI2: -2.9215061 | CJ2: -2.9230265 | CK2: -2.9476846 | CL2: -3.1108479 | CM2: -3.1548417 | CN2: -3.4695892 | CO2: -3.6918841 | CP2: -3.7111553 | CQ2: -3.6950299 | CR2: -3.8599645 | CS2: -3.882508 | CT2: -3.8615899 | CU2: -3.7982734 | CV2: -3.4452956 | CW2: -3.2708669 | CX2: -3.1469644 | CY2: -2.9005626 | CZ2: -2.6533759 | DA2: -2.5445836 | DB2: -2.4908267 | DC2: -2.1391069 | DD2: -2.0098537 | DE2: -1.938457 | DF2: -1.7871456 | DG2: -1.5213628 | DH2: -1.4239354 | DI2: -1.3156376 | DJ2: -1.2005733 | DK2: -1.0451497 | DL2: -0.76927017 | DM2: -0.55231267 | DN2: -0.67346471 | DO2: -0.636352 | DP2: -0.52260792 | DQ2: -0.39543 | DR2: -0.50434917 | DS2: -0.47883515 | DT2: -0.33957477 | DU2: -0.21493649 | DV2: -0.05166152 | DW2: 0.09357456 | DX2: 0.23755939 | DY2: 0.39932625 | DZ2: 0.61821177 | EA2: 0.88419047 | EB2: 1.0543923 | EC2: 1.2151564 | ED2: 1.387084 | EE2: 1.7022566 | EF2: 1.905461 | EG2: 2.1007723 | EH2: 2.2904164 | EI2: 2.1097141 | EJ2: 1.9306713 | EK2: 2.1157274 | EL2: 2.3018431 | EM2: 2.5224991 | EN2: 2.4609519 | EO2: 2.6373685 | EP2: 2.804416 | EQ2: 3.1223243 | ER2: 3.5543254 | ES2: 3.9707871 | ET2: 4.116296 | EU2: 4.2147446 | EV2: 4.2838835 | EW2: 4.6043339 | EX2: 4.7610693 | EY2: 4.6986588 | EZ2: 4.5582558 | FA2: 4.5373433 | FB2: 4.6814319 | FC2: 4.6408807 | FD2: 4.5494705 | FE2: 4.4475321 | FF2: 4.3449241 | FG2: 4.2920149 | FH2: 3.6810414 | FI2: 3.436594 | FJ2: 3.2728109 | FK2: 3.0995297 | FL2: 2.8441849 | FM2: 2.6465544 | FN2: 2.4505093 | FO2: 2.2119475 | FP2: 1.8800673 | FQ2: 1.5377578 | FR2: 1.2937375 | FS2: 1.0458161 | FT2: 0.79064773 | FU2: 0.47460588 | FV2: 0.21278743 | FW2: -0.033126361 | FX2: -0.27510759 | FY2: -0.47734051 | FZ2: -0.66122921 | GA2: -0.86387602 | GB2: -1.0562003 | GC2: -1.2300795 | GD2: -1.2832324 | GE2: -1.4338009 | GF2: -1.5586687 | GG2: -1.6908152 | GH2: -1.7891742 | GI2: -1.8882582 | GJ2: -1.997544 | GK2: -2.157493 | GL2: -2.4611385 | GM2: -2.5532624 | GN2: -2.621572 | GO2: -2.9576286 | GP2: -3.393387 | GQ2: -3.427255 | GR2: -3.4690278 | GS2: -3.2684284 | GT2: -3.2235739 | GU2: -3.201462 | GV2: -3.0130914 | GW2: -2.734349 | GX2: -2.660425 | GY2: -2.5461371 | GZ2: -2.2393767 | HA2: -2.0619249 | HB2: -1.9793689 | HC2: -1.932378 | HD2: -1.6234232 | HE2: -1.5049137 | HF2: -1.3804633 | HG2: -1.2597295 | HH2: -1.1630311 | HI2: -1.0467612 | HJ2: -0.91575401 | HK2: -0.88883681 | HL2: -1.130272 | HM2: -1.0178687 | HN2: -0.91522992 | HO2: -0.83556067 | HP2: -1.010736 | HQ2: -0.93050695 | HR2: -0.8197025 | HS2: -0.7355407 | HT2: -0.54593009 | HU2: -0.43739097 | HV2: -0.36153381 | HW2: -0.30277117 | HX2: -0.15930436 | HY2: 0.06916527 | HZ2: 0.10388151 | IA2: 0.13216933 | IB2: 0.18707699 | IC2: 0.30731316 | ID2: 0.36451409 | IE2: 0.37579226 | IF2: 0.4116662 | IG2: 0.26118021 | IH2: -0.3633273 | II2: -0.34929875 | IJ2: -0.3220531 | IK2: -0.30960489 | IL2: -0.46422507 | IM2: -0.56397585 | IN2: -0.55444183 | IO2: -0.53891698 | IP2: -0.50293495 | IQ2: -0.13554424 | IR2: 0.011328908 | IS2: 0.033223135 | IT2: 0.054996428 | IU2: 0.085997955 | IV2: 0.45360352 | IW2: 0.51479911 | IX2: 0.53363492 | IY2: 0.54202918 | IZ2: 0.67106444 | JA2: 0.90396831 | JB2: 0.92575867 | JC2: 0.9696789 | JD2: 1.0172522 | JE2: 1.166214 | JF2: 1.2694183 | JG2: 1.333695 | JH2: 1.3565972 | JI2: 1.4110836 | JJ2: 1.417014 | JK2: 1.473759 | JL2: 1.5165938 | JM2: 1.5630444 | JN2: 1.3819515 | JO2: 1.3873615 | JP2: 1.450284 | JQ2: 1.5129607 | JR2: 1.4520682 | JS2: 1.4387363 | JT2: 1.4229468 | JU2: 1.4690547 | JV2: 1.5384456 | JW2: 1.5824306 | JX2: 1.6200276 | JY2: 1.6448266 | JZ2: 1.7674245 | KA2: 1.7825236 | KB2: 1.7897813 | KC2: 1.7774909 | KD2: 1.732703 | KE2: 1.7226601 | KF2: 1.7142671 | KG2: 1.4973149 | KH2: 1.3799479 | KI2: 1.366963 | KJ2: 1.2933622 | KK2: 1.0980407 | KL2: 1.0257912 | KM2: 0.947205 | KN2: 0.93325306 | KO2: 0.84059337 | KP2: 0.62581604 | KQ2: 0.50774653 | KR2: 0.58810087 | KS2: 0.52788384 | KT2: 0.4192372 | KU2: 0.29406057 | KV2: 0.33907441 | KW2: 0.27273609 | KX2: 0.15330756 | KY2: 0.047481457 | KZ2: 0.025845013 | LA2: -0.043027287 | LB2: -0.13562087 | LC2: -0.23341084 | LD2: -0.35758969 | LE2: -0.49024683 | LF2: -0.5795915 | LG2: -0.64672534 | LH2: -0.88483236 | LI2: -1.3440897 | LJ2: -1.439742 | LK2: -1.5096288 | LL2: -1.5819197 | LM2: -1.7611448 | LN2: -1.8566954 | LO2: -1.8957413 | LP2: -1.9124669 | LQ2: -1.9041589 | LR2: -1.7469263 | LS2: -1.7347626 | LT2: -1.6963957 | LU2: -1.6332834 | LV2: -1.407038 | LW2: -1.2764986 | LX2: -1.2149025 | LY2: -1.11161 | LZ2: -0.98910927 | MA2: -0.74004721 | MB2: -0.63145247 | MC2: -0.56406389 | MD2: -0.47730531 | ME2: -1.0191059 | MF2: -1.0977408 | MG2: -1.0057759 | MH2: -0.90979887 | MI2: -0.90251125 | MJ2: -1.083802 | MK2: -0.94894629 | ML2: -0.82435681 | MM2: -0.68133696 | MN2: -0.15837662 | MO2: 0.025385754 | MP2: 0.16939685 | MQ2: 0.24583012 | MR2: 0.43577385 | MS2: 0.81321302 | MT2: 0.85135177 | MU2: 0.90103921 | MV2: 0.92383214 | MW2: 1.2022006 | MX2: 1.2401217 | MY2: 1.2352774 | MZ2: 1.2444367 | NA2: 1.2769503 | NB2: 1.3221369 | NC2: 1.2860332 | ND2: 1.2536797 | NE2: 1.1783552 | NF2: 1.0524962 | NG2: 0.99765139 | NH2: 0.90581607 | NI2: 0.81933787 | NJ2: 0.51077757 | NK2: 0.38532832 | NL2: 0.29650634 | NM2: 0.19570954 | NN2: -0.02601308 | NO2: -0.16028044 | NP2: -0.26019586 | NQ2: -0.35782974 | NR2: -0.41876002 | NS2: -0.51818836 | NT2: -0.62439649 | NU2: -0.70543291 | NV2: -0.71643829 | NW2: -0.81266785 | NX2: -0.89388013 | NY2: -0.9979957 | NZ2: -1.127807 | OA2: -1.2068331 | OB2: -1.2640081 | OC2: -1.4791978 | OD2: -1.6972126 | OE2: -1.7973091 | OF2: -1.8838524 | OG2: -2.0577726 | OH2: -2.16608 | OI2: -2.2019723 | OJ2: -2.2367804 | OK2: -2.015702 | OL2: -1.9885446 | OM2: -1.9635043 | ON2: -1.9377384 | OO2: -1.5364559 | OP2: -1.4308095 | OQ2: -1.3604277 | OR2: -1.2712419 | OS2: -0.89146452 | OT2: -0.75881361 | OU2: -0.63866801 | OV2: -0.5231185 | OW2: -0.23519122 | OX2: -0.046209647 | OY2: 0.061568103 | OZ2: 0.2238948 | PA2: 0.33676994 | PB2: 0.45570394 | PC2: 0.61453666 | PD2: 0.76346534 | PE2: 0.81401374 | PF2: 0.49214369 | PG2: 0.63793871 | PH2: 0.74344276 | PI2: 0.88226601 | PJ2: 0.74695943 | PK2: 0.80705083 | PL2: 0.928353 | PM2: 1.0213941 | PN2: 1.2131166 | PO2: 1.4202306 | PP2: 1.498578 | PQ2: 1.5831488 | PR2: 1.6555802 | PS2: 1.9193014 | PT2: 1.9984977 | PU2: 2.0355963 | PV2: 2.013041 | PW2: 2.0725416 | PX2: 2.2444087 | PY2: 2.2439828 | PZ2: 2.2472112 | QA2: 2.2312008 | QB2: 1.5801877 | QC2: 1.4860952 | QD2: 1.4791074 | QE2: 1.4784133 | QF2: 1.2951827 | QG2: 1.0074887 | QH2: 0.95320476 | QI2: 0.9298395 | QJ2: 0.84985578 | QK2: 1.1365285 | QL2: 1.1000132 | QM2: 0.98812856 | QN2: 0.88575516 | QO2: 0.91338777 | QP2: 1.0226494 | QQ2: 0.89767076 | QR2: 0.78101241 | QS2: 0.70917977 | QT2: 0.80057214 | QU2: 0.700032 | QV2: 0.61271863 | QW2: 0.52227393 | QX2: 0.51319475 | QY2: 0.44727923 | QZ2: 0.37642055 | RA2: 0.28117376 | RB2: 0.13632363 | RC2: 0.045424996 | RD2: -0.024454669 | RE2: -0.080474123 | RF2: -0.37648463 | RG2: -0.47112474 | RH2: -0.50958277 | RI2: -0.55188221 | RJ2: -0.73129319 | RK2: -0.7528168 | RL2: -0.7709423 | RM2: -0.78264077 | RN2: -0.72251529 | RO2: -0.74511928 | RP2: -0.75051491 | RQ2: -0.6934213 | RR2: -0.61895996 | RS2: -0.62406369 | RT2: -0.64135507 | RU2: -0.64323754 | RV2: -0.6534199 | RW2: -0.67241368 | RX2: -0.67704179 | RY2: -1.0115745 | RZ2: -1.130227 | SA2: -1.1734452 | SB2: -1.2076049 | SC2: -1.4373534 | SD2: -1.5544903 | SE2: -1.6190639 | SF2: -1.6811731 | SG2: -1.5901396 | SH2: -1.5383796 | SI2: -1.5876846 | SJ2: -1.6614727 | SK2: -1.6712998 | SL2: -1.4506274 | SM2: -1.511049 | SN2: -1.5749954 | SO2: -1.6574454 | SP2: -1.5528914 | SQ2: -1.5651036

Sheet H2O_thicknesses
A1: 452000 | B1: 451000 | C1: 450000 | D1: 449000 | E1: 448000 | F1: 447000 | G1: 446000 | H1: 445000 | I1: 444000 | J1: 443000 | K1: 442000 | L1: 441000 | M1: 440000 | N1: 439000 | O1: 438000 | P1: 437000 | Q1: 436000 | R1: 435000 | S1: 434000 | T1: 433000 | U1: 432000 | V1: 431000 | W1: 430000 | X1: 429000 | Y1: 428000 | Z1: 427000 | AA1: 426000 | AB1: 425000 | AC1: 424000 | AD1: 423000 | AE1: 422000 | AF1: 421000 | AG1: 420000 | AH1: 419000 | AI1: 418000 | AJ1: 417000 | AK1: 416000 | AL1: 415000 | AM1: 414000 | AN1: 413000 | AO1: 412000 | AP1: 411000 | AQ1: 410000 | AR1: 409000 | AS1: 408000 | AT1: 407000 | AU1: 406000 | AV1: 405000 | AW1: 404000 | AX1: 403000 | AY1: 402000 | AZ1: 401000 | BA1: 400000 | BB1: 399000 | BC1: 398000 | BD1: 397000 | BE1: 396000 | BF1: 395000 | BG1: 394000 | BH1: 393000 | BI1: 392000 | BJ1: 391000 | BK1: 390000 | BL1: 389000 | BM1: 388000 | BN1: 387000 | BO1: 386000 | BP1: 385000 | BQ1: 331000 | BR1: 330000 | BS1: 329000 | BT1: 328000 | BU1: 327000 | BV1: 326000 | BW1: 325000 | BX1: 324000 | BY1: 323000 | BZ1: 322000 | CA1: 321000 | CB1: 320000 | CC1: 319000 | CD1: 318000 | CE1: 317000 | CF1: 316000 | CG1: 315000 | CH1: 314000 | CI1: 313000 | CJ1: 312000 | CK1: 311000 | CL1: 310000 | CM1: 309000 | CN1: 308000 | CO1: 307000 | CP1: 306000 | CQ1: 305000 | CR1: 304000 | CS1: 303000 | CT1: 302000 | CU1: 301000 | CV1: 300000 | CW1: 299000 | CX1: 298000 | CY1: 297000 | CZ1: 296000 | DA1: 295000 | DB1: 294000 | DC1: 293000 | DD1: 292000 | DE1: 291000 | DF1: 290000 | DG1: 289000 | DH1: 288000 | DI1: 287000 | DJ1: 286000 | DK1: 285000 | DL1: 284000 | DM1: 283000 | DN1: 282000 | DO1: 281000 | DP1: 280000 | DQ1: 279000 | DR1: 278000 | DS1: 269000 | DT1: 268000 | DU1: 267000 | DV1: 266000 | DW1: 265000 | DX1: 264000 | DY1: 263000 | DZ1: 262000 | EA1: 261000 | EB1: 260000 | EC1: 197000 | ED1: 196000 | EE1: 195000 | EF1: 194000 | EG1: 193000 | EH1: 192000 | EI1: 191000 | EJ1: 190000 | EK1: 189000 | EL1: 188000 | EM1: 187000 | EN1: 186000 | EO1: 185000 | EP1: 184000 | EQ1: 183000 | ER1: 182000 | ES1: 181000 | ET1: 180000 | EU1: 179000 | EV1: 178000 | EW1: 177000 | EX1: 176000 | EY1: 175000 | EZ1: 174000 | FA1: 173000 | FB1: 172000 | FC1: 171000 | FD1: 170000 | FE1: 169000 | FF1: 168000 | FG1: 167000 | FH1: 166000 | FI1: 165000 | FJ1: 164000 | FK1: 163000 | FL1: 162000 | FM1: 161000 | FN1: 160000 | FO1: 159000 | FP1: 132000 | FQ1: 131000 | FR1: 130000 | FS1: 129000 | FT1: 128000 | FU1: 127000 | FV1: 126000 | FW1: 125000 | FX1: 124000 | FY1: 123000 | FZ1: 122000 | GA1: 121000 | GB1: 120000 | GC1: 119000 | GD1: 118000 | GE1: 117000 | GF1: 116000 | GG1: 115000 | GH1: 114000 | GI1: 113000 | GJ1: 112000 | GK1: 111000 | GL1: 110000 | GM1: 109000 | GN1: 108000 | GO1: 107000 | GP1: 106000 | GQ1: 105000 | GR1: 104000 | GS1: 103000 | GT1: 102000 | GU1: 101000 | GV1: 100000 | GW1: 99000 | GX1: 98000 | GY1: 97000 | GZ1: 38000 | HA1: 37000 | HB1: 36000 | HC1: 35000 | HD1: 34000 | HE1: 33000 | HF1: 32000 | HG1: 31000 | HH1: 30000 | HI1: 29000 | HJ1: 28000 | HK1: 27000 | HL1: 26000 | HM1: 25000 | HN1: 24000 | HO1: 23000 | HP1: 22000 | HQ1: 21000 | HR1: 20000 | HS1: 19000 | HT1: 18000 | HU1: 17000 | HV1: 16000 | HW1: 15000 | HX1: 14000 | HY1: 13000 | HZ1: 12000 | IA1: 11000 | IB1: 10000 | IC1: 9000 | ID1: 8000 | IE1: 7000 | IF1: 6000 | IG1: 5000 | IH1: 4000 | II1: 3000 | IJ1: 2000 | IK1: 1000 | IL1: 0
A2: 0.21828776 | B2: 0.24215456 | C2: 0.24807319 | D2: 0.26861053 | E2: 0.26001098 | F2: 0.25678732 | G2: 0.25201905 | H2: 0.2861477 | I2: 0.27264695 | J2: 0.26389011 | K2: 0.25907821 | L2: 0.265558 | M2: 0.27327366 | N2: 0.26955373 | O2: 0.27249411 | P2: 0.26874495 | Q2: 0.26749728 | R2: 0.27415051 | S2: 0.27000791 | T2: 0.26524397 | U2: 0.2511084 | V2: 0.25178041 | W2: 0.25097508 | X2: 0.24957353 | Y2: 0.24824671 | Z2: 0.24419049 | AA2: 0.23768831 | AB2: 0.23745191 | AC2: 0.23243917 | AD2: 0.23047765 | AE2: 0.23115655 | AF2: 0.23253753 | AG2: 0.23370478 | AH2: 0.24201964 | AI2: 0.24658609 | AJ2: 0.24709026 | AK2: 0.24658144 | AL2: 0.2505348 | AM2: 0.25112196 | AN2: 0.25100135 | AO2: 0.25829207 | AP2: 0.24822837 | AQ2: 0.24387064 | AR2: 0.24031476 | AS2: 0.23410792 | AT2: 0.22831784 | AU2: 0.22510669 | AV2: 0.22416794 | AW2: 0.21369498 | AX2: 0.20984628 | AY2: 0.20875584 | AZ2: 0.2041695 | BA2: 0.20096251 | BB2: 0.1976989 | BC2: 0.19407114 | BD2: 0.19021672 | BE2: 0.18942701 | BF2: 0.17901979 | BG2: 0.17083533 | BH2: 0.17540564 | BI2: 0.17400561 | BJ2: 0.16971475 | BK2: 0.16452326 | BL2: 0.16852362 | BM2: 0.16758654 | BN2: 0.16247182 | BO2: 0.15789414 | BP2: 0.15189741 | BQ2: 0.18527111 | BR2: 0.20147569 | BS2: 0.22130597 | BT2: 0.21989878 | BU2: 0.22341294 | BV2: 0.22648427 | BW2: 0.22209803 | BX2: 0.22407294 | BY2: 0.23052385 | BZ2: 0.2361563 | CA2: 0.23610234 | CB2: 0.24087067 | CC2: 0.24142253 | CD2: 0.24450458 | CE2: 0.25226863 | CF2: 0.25609669 | CG2: 0.23610691 | CH2: 0.2447312 | CI2: 0.25720114 | CJ2: 0.25667647 | CK2: 0.25797669 | CL2: 0.24765877 | CM2: 0.24096293 | CN2: 0.23814362 | CO2: 0.23295734 | CP2: 0.2225482 | CQ2: 0.22058684 | CR2: 0.21752806 | CS2: 0.20939223 | CT2: 0.20394353 | CU2: 0.20178372 | CV2: 0.20050889 | CW2: 0.19243336 | CX2: 0.18933574 | CY2: 0.18595489 | CZ2: 0.18281032 | DA2: 0.18029176 | DB2: 0.17726345 | DC2: 0.17395189 | DD2: 0.17324786 | DE2: 0.17956269 | DF2: 0.17662274 | DG2: 0.17393819 | DH2: 0.17382256 | DI2: 0.17881696 | DJ2: 0.17652956 | DK2: 0.17337043 | DL2: 0.17110929 | DM2: 0.16566765 | DN2: 0.16255269 | DO2: 0.16037566 | DP2: 0.15868923 | DQ2: 0.15457188 | DR2: 0.14801503 | DS2: 0.18367782 | DT2: 0.18595677 | DU2: 0.18315211 | DV2: 0.18538185 | DW2: 0.25080644 | DX2: 0.38239138 | DY2: 0.16591193 | DZ2: 0.16546638 | EA2: 0.16443373 | EB2: 0.15388999 | EC2: 0.39308345 | ED2: 0.35126031 | EE2: 0.30845367 | EF2: 0.27807531 | EG2: 0.26325063 | EH2: 0.24978727 | EI2: 0.245419 | EJ2: 0.24342317 | EK2: 0.23952073 | EL2: 0.22799036 | EM2: 0.23060747 | EN2: 0.23475345 | EO2: 0.23132875 | EP2: 0.22877446 | EQ2: 0.21281598 | ER2: 0.21098915 | ES2: 0.20518748 | ET2: 0.20399608 | EU2: 0.20068733 | EV2: 0.19608805 | EW2: 0.188739 | EX2: 0.18514495 | EY2: 0.18223399 | EZ2: 0.17948186 | FA2: 0.17587681 | FB2: 0.16936092 | FC2: 0.16651989 | FD2: 0.16474362 | FE2: 0.1624759 | FF2: 0.17654315 | FG2: 0.17871183 | FH2: 0.17630645 | FI2: 0.17593916 | FJ2: 0.17590118 | FK2: 0.18110404 | FL2: 0.1775167 | FM2: 0.17390396 | FN2: 0.17011055 | FO2: 0.15467469 | FP2: 0.15464767 | FQ2: 0.15768002 | FR2: 0.16065489 | FS2: 0.16269288 | FT2: 0.16735824 | FU2: 0.1735546 | FV2: 0.1766116 | FW2: 0.17631318 | FX2: 0.18069968 | FY2: 0.18519416 | FZ2: 0.18983503 | GA2: 0.19508853 | GB2: 0.19824791 | GC2: 0.20300687 | GD2: 0.23927925 | GE2: 0.26055968 | GF2: 0.27518416 | GG2: 0.32461953 | GH2: 0.38516358 | GI2: =GK2 -> 0.22492752 | GJ2: 0.21674316 | GK2: 0.22492752 | GL2: 0.22403222 | GM2: 0.22512009 | GN2: 0.22837333 | GO2: 0.22746873 | GP2: 0.21443212 | GQ2: 0.2363587 | GR2: 0.23862087 | GS2: 0.24873531 | GT2: 0.23263233 | GU2: 0.22811219 | GV2: 0.25215739 | GW2: 0.36555574 | GX2: 0.15674975 | GY2: 0.15132617 | GZ2: 0.18565936 | HA2: 0.24835533 | HB2: 0.24205652 | HC2: 0.22862669 | HD2: 0.22075595 | HE2: 0.22886156 | HF2: 0.21091265 | HG2: 0.20358562 | HH2: 0.19866329 | HI2: 0.19059431 | HJ2: 0.18849431 | HK2: 0.18824285 | HL2: 0.18337025 | HM2: 0.17978687 | HN2: 0.17856181 | HO2: 0.17809325 | HP2: 0.17817571 | HQ2: 0.17715181 | HR2: 0.17208578 | HS2: 0.17223779 | HT2: 0.18240017 | HU2: 0.18570522 | HV2: 0.18506187 | HW2: 0.18407624 | HX2: 0.18957365 | HY2: 0.191244 | HZ2: 0.19294044 | IA2: 0.1939824 | IB2: 0.19156339 | IC2: 0.19006791 | ID2: 0.19135208 | IE2: 0.19345645 | IF2: 0.19765021 | IG2: 0.19135865 | IH2: 0.19336561 | II2: 0.19567031 | IJ2: 0.19892165 | IK2: 0.19623957 | IL2: 0.19660321
